Workbook

Sheet HuongDan
A1: Bảng tính ngân sách & vận hành — Xưởng Video AI: kênh REVIEW (Global, tiếng Anh)
A2: v2 — 13/10/2026. Ngách: SaaS, AI tool, sản phẩm vật lý (SPVL), Crypto, Forex. Video dài tối thiểu 15 phút. Giá công cụ là ảnh chụp tháng 9–10/2026 — xác nhận khi thanh toán.
A4: Quy ước màu
A5: Chữ xanh dương | B5: Ô nhập liệu / giả định — được phép sửa
A6: Nền vàng | B6: Giả định quan trọng nhất — nên rà lại trước khi trình bày
A7: Chữ đen | B7: Công thức — KHÔNG sửa tay
A8: Chữ xanh lá | B8: Công thức lấy dữ liệu từ sheet khác
A10: Hai kênh
A11: Kênh A — Tech & AI Tools | B11: SaaS, AI tool, SPVL công nghệ. Có NGƯỜI DẪN AI trông như người thật (HeyGen) + quay màn hình sản phẩm thật.
A12: Kênh B — Crypto & Forex | B12: Sàn crypto, broker forex, công cụ giao dịch. KHÔNG người dẫn AI (chính sách YouTube về AI persona tài chính). Chỉ chạy khi có ý kiến luật sư.
A14: Các sheet
A15: ThongSo | B15: Giả định đầu vào: tỷ giá, độ dài video, cơ cấu hình ảnh theo cấp, đơn giá credit Veo/HeyGen/ElevenLabs
A16: CongCu | B16: Công cụ, giá/tháng, hạn mức credit và 3 gói ngân sách A – B – C
A17: ChiPhiVideo | B17: Khối lượng & chi phí 1 video dài 18 phút (3 cấp Kênh A + Kênh B); thuê bao vs API; chi phí trọn gói; kiểm tra đủ credit; mục E: phương án HeyGen Video Agent
A18: NangSuat | B18: Thời gian 10 bước, năng lực/ngày, trần đăng; so sánh thời gian với HeyGen Video Agent
A19: DoanhThu | B19: Doanh thu affiliate + quảng cáo, điểm hoà vốn, mục tiêu YPP Kênh A trước 31/01/2027
A20: LichDang | B20: Khung giờ đăng giờ VN ↔ New York
A21: TheoDoi | B21: Theo dõi sản xuất từng video (có cột tuân thủ & affiliate)
A22: KPI | B22: KPI hằng tuần, gồm click & chuyển đổi affiliate

Sheet ThongSo
A1: Thông số & giả định đầu vào
A2: Chữ xanh dương = được sửa. Mọi sheet khác tính từ đây.
A4: Thông số | B4: Giá trị | C4: Đơn vị | D4: Ghi chú / nguồn
A5: Tỷ giá USD → VND | B5: 26500 | C5: VND/USD | D5: Giả định lập kế hoạch. Vietcombank bán ra 26.465 (02/07/2026).
A6: Độ dài 1 video dài (lập ngân sách) | B6: 1080 | C6: giây | D6: 18 phút. Quy chuẩn kênh: tối thiểu 15 phút (900 giây), chuẩn 15–20 phút.
A7: Độ dài 1 clip AI | B7: 8 | C7: giây | D7: Veo 3.1 tạo clip 4/6/8 giây.
A8: Số ảnh phải tạo cho 1 ảnh dùng được | B8: 2 | C8: lần
A9: Ảnh phụ thêm mỗi video (thumbnail, nền người dẫn) | B9: 3 | C9: ảnh
A10: Số short cắt từ 1 video dài | B10: 5 | C10: short | D10: Kịch bản module: 5–7 phần tính năng/giá/so sánh/kết luận đứng độc lập.
A11: Độ dài 1 short native | B11: 45 | C11: giây
A12: Hệ số làm lại clip cho short native | B12: 2.5 | C12: lần
A13: Ký tự giọng đọc / phút | B13: 900 | C13: ký tự | D13: ≈150 từ tiếng Anh/phút.
A14: Hệ số làm lại giọng đọc | B14: 1.3 | C14: lần
A15: Số ngày làm việc / tháng | B15: 22 | C15: ngày
A16: Giờ làm hiệu quả / ngày / người | B16: 7 | C16: giờ
A17: HeyGen: credit / phút người dẫn (Avatar IV) | B17: 20 | C17: credit | D17: Nguồn thứ cấp ghi 16–31 credit/phút tuỳ loại Look; 20 là mức hay gặp nhất. Kiểm tra trên app.
A18: HeyGen: đơn giá 1 credit | B18: =49/1000 -> 0.049 | C18: USD | D18: Gói Pro US$49 / 1.000 credit (heygen.com/pricing, 10/2026).
A19: Hệ số làm lại đoạn người dẫn | B19: 1.3 | C19: lần
A21: Cơ cấu hình ảnh theo cấp (tỷ lệ thời lượng video dài)
A22: Tham số | B22: A · Tiết kiệm | C22: A · Tiêu chuẩn | D22: A · Cao cấp | E22: B · Tài chính (không host AI) | F22: Ghi chú
A23: Người dẫn AI trông như người thật (HeyGen) | B23: 0.15 | C23: 0.2 | D23: 0.25 | E23: 0 | F23: Kênh B = 0: YouTube không trả tiền cho kênh dùng nhân vật AI tư vấn tài chính.
A24: B-roll người thật do AI tạo (Veo 3.1) | B24: 0.15 | C24: 0.2 | D24: 0.3 | E24: 0.2 | F24: Người dùng laptop, văn phòng, giao dịch… không nói, không tư vấn.
A25: Quay màn hình / hình sản phẩm thật | B25: 0.5 | C25: 0.4 | D25: 0.3 | E25: 0.55 | F25: Dữ liệu thật — bắt buộc để review hợp lệ (FTC).
A26: Đồ hoạ: bảng giá, so sánh, chấm điểm | B26: 0.2 | C26: 0.2 | D26: 0.15 | E26: 0.25 | F26: Template CapCut/Canva — không tốn credit.
A27: Kiểm tra: tổng cơ cấu = 100% | B27: =IF(ABS(SUM(B23:B26)-1)<0.0001,"OK","SAI") -> OK | C27: =IF(ABS(SUM(C23:C26)-1)<0.0001,"OK","SAI") -> OK | D27: =IF(ABS(SUM(D23:D26)-1)<0.0001,"OK","SAI") -> OK | E27: =IF(ABS(SUM(E23:E26)-1)<0.0001,"OK","SAI") -> OK
A28: Hệ số làm lại clip B-roll | B28: 2 | C28: 2.5 | D28: 3 | E28: 2.5 | F28: Người thật khó hơn phong cảnh.
A29: Tỷ trọng Veo 3.1 Lite | B29: 0.5 | C29: 0.1 | D29: 0 | E29: 0.1
A30: Tỷ trọng Veo 3.1 Fast | B30: 0.5 | C30: 0.85 | D30: 0.7 | E30: 0.85
A31: Tỷ trọng Veo 3.1 Quality | B31: 0 | C31: 0.05 | D31: 0.3 | E31: 0.05 | F31: Cận cảnh người cần chất lượng cao.
A32: Kiểm tra: tổng tỷ trọng model = 100% | B32: =IF(ABS(SUM(B29:B31)-1)<0.0001,"OK","SAI") -> OK | C32: =IF(ABS(SUM(C29:C31)-1)<0.0001,"OK","SAI") -> OK | D32: =IF(ABS(SUM(D29:D31)-1)<0.0001,"OK","SAI") -> OK | E32: =IF(ABS(SUM(E29:E31)-1)<0.0001,"OK","SAI") -> OK
A34: Đơn giá Veo 3.1 (credit Flow / clip 8 giây và API USD / giây)
A35: Model | B35: Credit/clip — Google AI Pro | C35: Credit/clip — Google AI Ultra | D35: API USD/giây (1080p) | E35: Nguồn
A36: Veo 3.1 Lite | B36: 10 | C36: 5 | D36: 0.08 | E36: diyai.io (cập nhật 20/09/2026); Gemini API pricing
A37: Veo 3.1 Fast | B37: 20 | C37: 10 | D37: 0.12 | E37: diyai.io (cập nhật 20/09/2026); Gemini API pricing
A38: Veo 3.1 Quality | B38: 100 | C38: 100 | D38: 0.4 | E38: diyai.io (cập nhật 20/09/2026); Gemini API pricing
A40: Đơn giá khác
A41: Thông số | B41: Giá trị | C41: Đơn vị | D41: Ghi chú / nguồn
A42: Ảnh Nano Banana Pro qua API | B42: 0.134 | C42: USD/ảnh | D42: Chỉ dùng cho tuyến API.
A43: Ảnh trong thuê bao Google AI (quy đổi) | B43: 0 | C43: USD/ảnh | D43: Đã gồm trong AI Pro/Ultra (có giới hạn theo ngày).
A44: Giọng đọc ElevenLabs | B44: =99/600 -> 0.165 | C44: USD/1.000 ký tự | D44: Gói Pro US$99 / 600.000 credit.
...

Sheet CongCu
A1: Bộ công cụ, hạn mức & 3 gói ngân sách / tháng
A2: SL = số lượng thuê bao trong gói. Hạn mức = credit/ký tự mỗi tháng của 1 thuê bao (dùng để kiểm tra đủ tài nguyên). Giá có dấu * là ước tính — xác nhận khi mua.
A4: STT | B4: Công cụ | C4: Vai trò | D4: Gói | E4: USD/tháng | F4: Loại hạn mức | G4: Hạn mức/tháng | H4: Ghi chú | I4: SL gói A | J4: SL gói B | K4: SL gói C
A5: 1 | B5: Claude | C5: Bộ não: nghiên cứu sản phẩm, kịch bản, QC tuân thủ, SEO, phân tích | D5: Pro | E5: 20 | I5: 1 | J5: 0 | K5: 0
A6: 2 | B6: Claude | C6: Như trên + Claude Code tự động hoá | D6: Max 5x | E6: 100 | I6: 0 | J6: 1 | K6: 0
A7: 3 | B7: Claude | C7: Như trên, 2 người vận hành | D7: Max 20x | E7: 200 | I7: 0 | J7: 0 | K7: 1
A8: 4 | B8: Claude API | C8: Tool cắt short | D8: Theo dùng | E8: 10 | H8: Ước tính | I8: 0 | J8: 1 | K8: 3
A9: 5 | B9: Google AI (Flow) | C9: Veo 3.1 B-roll người thật + Nano Banana Pro | D9: AI Pro | E9: 19.99 | F9: Flow | G9: 2500 | H9: 1.000 credit + 50/ngày | I9: 1 | J9: 0 | K9: 0
A10: 6 | B10: Google AI (Flow) | C10: Như trên, sản lượng lớn | D10: AI Ultra 20x | E10: 199.99 | F10: Flow | G10: 26500 | H10: 25.000 credit + 50/ngày; kiểm tra khả dụng tại VN | I10: 0 | J10: 1 | K10: 2
A11: 7 | B11: HeyGen | C11: Người dẫn AI (Avatar IV) — chỉ Kênh A | D11: Creator | E11: 29 | F11: HeyGen | G11: 600 | H11: Video tối đa 30 phút | I11: 1 | J11: 0 | K11: 0
A12: 8 | B12: HeyGen | C12: Như trên | D12: Pro ~1.500 credit* | E12: 74 | F12: HeyGen | G12: 1500 | H12: *Ước tính theo US$49/1.000 credit | I12: 0 | J12: 1 | K12: 0
A13: 9 | B13: HeyGen | C13: Như trên | D13: Pro ~3.000 credit* | E13: 147 | F13: HeyGen | G13: 3000 | H13: *Ước tính theo US$49/1.000 credit | I13: 0 | J13: 0 | K13: 1
A14: 10 | B14: ElevenLabs | C14: Giọng đọc (dùng chung cho người dẫn + lời kể) | D14: Creator | E14: 22 | F14: ElevenLabs | G14: 121000 | H14: Tháng đầu US$11 | I14: 1 | J14: 0 | K14: 0
A15: 11 | B15: ElevenLabs | C15: Như trên | D15: Pro | E15: 99 | F15: ElevenLabs | G15: 600000 | I15: 0 | J15: 1 | K15: 2
A16: 12 | B16: Kling AI | C16: Dự phòng B-roll | D16: Standard | E16: 10 | H16: Chỉ gói trả phí được dùng thương mại | I16: 0 | J16: 1 | K16: 0
A17: 13 | B17: Kling AI | C17: Như trên | D17: Pro | E17: 37 | I17: 0 | J17: 0 | K17: 1
A18: 14 | B18: CapCut | C18: Dựng, phụ đề, zoom màn hình, template | D18: Pro | E18: 10 | H18: ≈220–290 nghìn ₫ tại VN | I18: 1 | J18: 1 | K18: 2
A19: 15 | B19: Suno | C19: Nhạc chủ đề | D19: Pro | E19: 10 | H19: Từ Pro mới có quyền thương mại | I19: 0 | J19: 1 | K19: 0
A20: 16 | B20: Suno | C20: Như trên | D20: Premier | E20: 30 | I20: 0 | J20: 0 | K20: 1
A21: 17 | B21: OpusClip | C21: Cắt short tự động (thay được bằng tool Claude) | D21: Pro | E21: 29 | H21: 300 phút xử lý/tháng | I21: 0 | J21: 1 | K21: 2
A22: 18 | B22: Ngân sách dùng thử sản phẩm | C22: Mua gói SaaS/AI tool để test thật (đơn vị US$50) | D22: Theo nhu cầu | E22: 50 | H22: Nhiều hãng cấp tài khoản review miễn phí | I22: 1 | J22: 3 | K22: 6
A23: 19 | B23: OBS + YouTube Audio Library | C23: Ghi màn hình, nhạc nền | D23: Miễn phí | E23: 0 | I23: 1 | J23: 1 | K23: 1
H25: Cộng thuê bao (USD/tháng) | I25: =SUMPRODUCT($E$5:$E$23,I5:I23) -> 150.99 | J25: =SUMPRODUCT($E$5:$E$23,J5:J23) -> 691.99 | K25: =SUMPRODUCT($E$5:$E$23,K5:K23) -> 1419.98
H26: Dự phòng phát sinh | I26: =I25*ThongSo!$B$46 -> 15.099 | J26: =J25*ThongSo!$B$46 -> 69.199 | K26: =K25*ThongSo!$B$46 -> 141.998
H27: TỔNG GÓI (USD/tháng) | I27: =I25+I26 -> 166.089 | J27: =J25+J26 -> 761.189 | K27: =K25+K26 -> 1561.978
H28: TỔNG GÓI (VND/tháng) | I28: =I27*ThongSo!$B$5 -> 4401358.5 | J28: =J27*ThongSo!$B$5 -> 20171508 | K28: =K27*ThongSo!$B$5 -> 41392417

Sheet ChiPhiVideo
A1: Chi phí cho 1 video dài (18 phút) theo cấp & theo kênh
A2: Tất cả là công thức từ ThongSo & CongCu. Đơn vị USD trừ khi ghi khác.
A4: Hạng mục | B4: A · Tiết kiệm | C4: A · Tiêu chuẩn | D4: A · Cao cấp | E4: B · Tài chính | F4: Cách tính
A5: A. Khối lượng sản xuất cho 1 video dài
A6: Giây người dẫn AI (HeyGen) | B6: =ThongSo!$B$6*ThongSo!B23 -> 162 | C6: =ThongSo!$B$6*ThongSo!C23 -> 216 | D6: =ThongSo!$B$6*ThongSo!D23 -> 270 | E6: =ThongSo!$B$6*ThongSo!E23 -> 0 | F6: Độ dài × tỷ lệ người dẫn
A7: Phút HeyGen phải tạo (gồm làm lại) | B7: =B6/60*ThongSo!$B$19 -> 3.51 | C7: =C6/60*ThongSo!$B$19 -> 4.68 | D7: =D6/60*ThongSo!$B$19 -> 5.85 | E7: =E6/60*ThongSo!$B$19 -> 0
A8: Credit HeyGen / video | B8: =B7*ThongSo!$B$17 -> 70.2 | C8: =C7*ThongSo!$B$17 -> 93.6 | D8: =D7*ThongSo!$B$17 -> 117 | E8: =E7*ThongSo!$B$17 -> 0
A9: Giây B-roll người thật AI | B9: =ThongSo!$B$6*ThongSo!B24 -> 162 | C9: =ThongSo!$B$6*ThongSo!C24 -> 216 | D9: =ThongSo!$B$6*ThongSo!D24 -> 324 | E9: =ThongSo!$B$6*ThongSo!E24 -> 216
A10: Số clip 8 giây dùng | B10: =B9/ThongSo!$B$7 -> 20.25 | C10: =C9/ThongSo!$B$7 -> 27 | D10: =D9/ThongSo!$B$7 -> 40.5 | E10: =E9/ThongSo!$B$7 -> 27
A11: Số clip phải tạo (gồm làm lại) | B11: =B10*ThongSo!B28 -> 40.5 | C11: =C10*ThongSo!C28 -> 67.5 | D11: =D10*ThongSo!D28 -> 121.5 | E11: =E10*ThongSo!E28 -> 67.5
A12: Credit TB / clip — gói Ultra | B12: =ThongSo!B29*ThongSo!$C$36+ThongSo!B30*ThongSo!$C$37+ThongSo!B31*ThongSo!$C$38 -> 7.5 | C12: =ThongSo!C29*ThongSo!$C$36+ThongSo!C30*ThongSo!$C$37+ThongSo!C31*ThongSo!$C$38 -> 14 | D12: =ThongSo!D29*ThongSo!$C$36+ThongSo!D30*ThongSo!$C$37+ThongSo!D31*ThongSo!$C$38 -> 37 | E12: =ThongSo!E29*ThongSo!$C$36+ThongSo!E30*ThongSo!$C$37+ThongSo!E31*ThongSo!$C$38 -> 14
A13: Credit TB / clip — gói Pro | B13: =ThongSo!B29*ThongSo!$B$36+ThongSo!B30*ThongSo!$B$37+ThongSo!B31*ThongSo!$B$38 -> 15 | C13: =ThongSo!C29*ThongSo!$B$36+ThongSo!C30*ThongSo!$B$37+ThongSo!C31*ThongSo!$B$38 -> 23 | D13: =ThongSo!D29*ThongSo!$B$36+ThongSo!D30*ThongSo!$B$37+ThongSo!D31*ThongSo!$B$38 -> 44 | E13: =ThongSo!E29*ThongSo!$B$36+ThongSo!E30*ThongSo!$B$37+ThongSo!E31*ThongSo!$B$38 -> 23
A14: Credit Flow / video — gói Ultra | B14: =B11*B12 -> 303.75 | C14: =C11*C12 -> 945 | D14: =D11*D12 -> 4495.5 | E14: =E11*E12 -> 945
A15: Credit Flow / video — gói Pro | B15: =B11*B13 -> 607.5 | C15: =C11*C13 -> 1552.5 | D15: =D11*D13 -> 5346 | E15: =E11*E13 -> 1552.5
A16: Giây quay màn hình / hình sản phẩm thật | B16: =ThongSo!$B$6*ThongSo!B25 -> 540 | C16: =ThongSo!$B$6*ThongSo!C25 -> 432 | D16: =ThongSo!$B$6*ThongSo!D25 -> 324 | E16: =ThongSo!$B$6*ThongSo!E25 -> 594 | F16: Không tốn credit, tốn thời gian người
A17: Tổng ảnh phải tạo | B17: =(B10+ThongSo!$B$9)*ThongSo!$B$8 -> 46.5 | C17: =(C10+ThongSo!$B$9)*ThongSo!$B$8 -> 60 | D17: =(D10+ThongSo!$B$9)*ThongSo!$B$8 -> 87 | E17: =(E10+ThongSo!$B$9)*ThongSo!$B$8 -> 60 | F17: Keyframe B-roll + thumbnail
A18: Ký tự giọng đọc (gồm đọc lại) | B18: =ThongSo!$B$6/60*ThongSo!$B$13*ThongSo!$B$14 -> 21060 | C18: =ThongSo!$B$6/60*ThongSo!$B$13*ThongSo!$B$14 -> 21060 | D18: =ThongSo!$B$6/60*ThongSo!$B$13*ThongSo!$B$14 -> 21060 | E18: =ThongSo!$B$6/60*ThongSo!$B$13*ThongSo!$B$14 -> 21060
A20: B. Chi phí biến đổi — tuyến THUÊ BAO (đề xuất)
A21: Video B-roll (credit × giá trị 1 credit Ultra 20x) | B21: =B14*CongCu!$E$10/CongCu!$G$10 -> 2.2923382 | C21: =C14*CongCu!$E$10/CongCu!$G$10 -> 7.1317189 | D21: =D14*CongCu!$E$10/CongCu!$G$10 -> 33.926605 | E21: =E14*CongCu!$E$10/CongCu!$G$10 -> 7.1317189 | F21: US$199,99 / 26.500 credit
A22: Người dẫn AI (credit HeyGen × đơn giá) | B22: =B8*ThongSo!$B$18 -> 3.4398 | C22: =C8*ThongSo!$B$18 -> 4.5864 | D22: =D8*ThongSo!$B$18 -> 5.733 | E22: =E8*ThongSo!$B$18 -> 0
A23: Ảnh | B23: =B17*ThongSo!$B$43 -> 0 | C23: =C17*ThongSo!$B$43 -> 0 | D23: =D17*ThongSo!$B$43 -> 0 | E23: =E17*ThongSo!$B$43 -> 0 | F23: Đã gồm trong thuê bao
A24: Giọng đọc | B24: =B18/1000*ThongSo!$B$44 -> 3.4749 | C24: =C18/1000*ThongSo!$B$44 -> 3.4749 | D24: =D18/1000*ThongSo!$B$44 -> 3.4749 | E24: =E18/1000*ThongSo!$B$44 -> 3.4749
A25: Cộng biến đổi / video dài (USD) | B25: =SUM(B21:B24) -> 9.2070382 | C25: =SUM(C21:C24) -> 15.193019 | D25: =SUM(D21:D24) -> 43.134505 | E25: =SUM(E21:E24) -> 10.606619
A26: Cộng biến đổi / video dài (VND) | B26: =B25*ThongSo!$B$5 -> 243986.51 | C26: =C25*ThongSo!$B$5 -> 402615 | D26: =D25*ThongSo!$B$5 -> 1143064.4 | E26: =E25*ThongSo!$B$5 -> 281075.4
A28: C. Tuyến API trả theo lượt (tham chiếu, KHÔNG khuyến nghị)
A29: Video (giây tạo × giá API bình quân) | B29: =B11*ThongSo!$B$7*(ThongSo!B29*ThongSo!$D$36+ThongSo!B30*ThongSo!$D$37+ThongSo!B31*ThongSo!$D$38) -> 32.4 | C29: =C11*ThongSo!$B$7*(ThongSo!C29*ThongSo!$D$36+ThongSo!C30*ThongSo!$D$37+ThongSo!C31*ThongSo!$D$38) -> 70.2 | D29: =D11*ThongSo!$B$7*(ThongSo!D29*ThongSo!$D$36+ThongSo!D30*ThongSo!$D$37+ThongSo!D31*ThongSo!$D$38) -> 198.288 | E29: =E11*ThongSo!$B$7*(ThongSo!E29*ThongSo!$D$36+ThongSo!E30*ThongSo!$D$37+ThongSo!E31*ThongSo!$D$38) -> 70.2 | F29: Veo 3.1 Gemini API
A30: Ảnh (Nano Banana Pro API) | B30: =B17*ThongSo!$B$42 -> 6.231 | C30: =C17*ThongSo!$B$42 -> 8.04 | D30: =D17*ThongSo!$B$42 -> 11.658 | E30: =E17*ThongSo!$B$42 -> 8.04
A31: Người dẫn AI | B31: =B22 -> 3.4398 | C31: =C22 -> 4.5864 | D31: =D22 -> 5.733 | E31: =E22 -> 0 | F31: Giữ cùng đơn giá
A32: Giọng đọc | B32: =B24 -> 3.4749 | C32: =C24 -> 3.4749 | D32: =D24 -> 3.4749 | E32: =E24 -> 3.4749
A33: Claude API | B33: =ThongSo!$B$45 -> 1 | C33: =ThongSo!$B$45 -> 1 | D33: =ThongSo!$B$45 -> 1 | E33: =ThongSo!$B$45 -> 1
A34: Cộng / video dài (USD) | B34: =SUM(B29:B33) -> 46.5457 | C34: =SUM(C29:C33) -> 87.3013 | D34: =SUM(D29:D33) -> 220.1539 | E34: =SUM(E29:E33) -> 82.7149
A35: API đắt gấp bao nhiêu lần thuê bao | B35: =IF(B25>0,B34/B25,0) -> 5.0554477 | C35: =IF(C25>0,C34/C25,0) -> 5.7461457 | D35: =IF(D25>0,D34/D25,0) -> 5.103893 | E35: =IF(E25>0,E34/E25,0) -> 7.7984229
A37: D. Chi phí TRỌN GÓI theo gói ngân sách + kiểm tra đủ tài nguyên
A38: Chỉ tiêu | B38: A | C38: B | D38: C | F38: Ghi chú
A39: Tên gói | B39: Thử nghiệm | C39: Tiêu chuẩn | D39: Mở rộng
A40: Cấp chất lượng Kênh A | B40: A · Tiết kiệm | C40: A · Tiêu chuẩn | D40: A · Tiêu chuẩn | F40: Gõ đúng: A · Tiết kiệm / A · Tiêu chuẩn / A · Cao cấp
A41: Loại gói Google AI | B41: Pro | C41: Ultra | D41: Ultra
A42: Video dài Kênh A / tháng | B42: 4 | C42: 12 | D42: 24
A43: Video dài Kênh B / tháng | B43: 0 | C43: 8 | D43: 16 | F43: Kênh B chỉ chạy khi có ý kiến luật sư (docs/09). Đặt 0 nếu chưa có.
A44: Short cắt từ video dài | B44: =(B42+B43)*ThongSo!$B$10 -> 20 | C44: =(C42+C43)*ThongSo!$B$10 -> 100 | D44: =(D42+D43)*ThongSo!$B$10 -> 200
...

Sheet NangSuat
A1: Năng suất: thời gian 10 bước & năng lực / ngày
A2: Phút thao tác của 1 người cho 1 video review dài ~18 phút, cấp Tiêu chuẩn.
A4: STT | B4: Bước | C4: Công cụ chính | D4: Phút — tháng đầu | E4: Phút — thành thạo | F4: Ghi chú
A5: 1 | B5: Chọn sản phẩm & nghiên cứu (affiliate, tính năng, giá, đối thủ) | C5: Claude + skill nghiên cứu affiliate | D5: 45 | E5: 25 | F5: Ưu tiên sản phẩm có chương trình affiliate
A6: 2 | B6: Dùng thử & quay màn hình sản phẩm (dữ liệu thật) | C6: OBS / CapCut recorder (hoặc Claude in Chrome) | D6: 60 | E6: 40 | F6: Bắt buộc: review phải dựa trên trải nghiệm thật
A7: 3 | B7: Kịch bản module + shot list + tuân thủ | C7: Claude (skill kich-ban-video) | D7: 45 | E7: 25 | F7: 2.250–3.000 từ
A8: 4 | B8: CỔNG 1 — duyệt kịch bản & tuân thủ | C8: Người + Claude (skill qc-video) | D8: 20 | E8: 10 | F8: Disclosure, cảnh báo rủi ro, không bịa trải nghiệm
A9: 5 | B9: Giọng đọc ~18 phút | C9: ElevenLabs | D9: 25 | E9: 12 | F9: Dùng chung cho người dẫn AI
A10: 6 | B10: Người dẫn AI (chỉ Kênh A) | C10: HeyGen Avatar IV (lồng từ file giọng) | D10: 30 | E10: 15 | F10: Kênh B bỏ bước này
A11: 7 | B11: B-roll người thật AI + ảnh | C11: Veo 3.1 / Nano Banana Pro | D11: 45 | E11: 25
A12: 8 | B12: Dựng: ráp màn hình, zoom, bảng giá, so sánh, phụ đề | C12: CapCut Pro (template kênh) | D12: 100 | E12: 55 | F12: Bước dài nhất
A13: 9 | B13: Thumbnail + SEO + link affiliate + disclosure | C13: Claude (skill seo-xuat-ban) + Nano Banana Pro | D13: 30 | E13: 15
A14: 10 | B14: CỔNG 2 — QC video, xuất, hẹn giờ | C14: Người + checklist | D14: 20 | E14: 12 | F14: Bật nhãn nội dung AI
B15: Tổng phút / 1 video dài | D15: =SUM(D5:D14) -> 420 | E15: =SUM(E5:E14) -> 234
B16: Tổng giờ / 1 video dài | D16: =D15/60 -> 7 | E16: =E15/60 -> 3.9
B18: Cắt 5 short từ 1 video dài + duyệt + hẹn giờ | C18: Tool cat_short.py / OpusClip | D18: 40 | E18: 25
B19: 1 short native dọc 9:16 | C19: Claude + HeyGen/Veo + CapCut | D19: 45 | E19: 30
A21: Năng lực 1 người / ngày
B22: Phút làm việc hiệu quả / ngày | D22: =ThongSo!$B$16*60 -> 420 | E22: =ThongSo!$B$16*60 -> 420
B23: Số video dài tối đa / ngày (kèm cắt short) | D23: =D22/(D15+D18) -> 0.91304348 | E23: =E22/(E15+E18) -> 1.6216216
A25: Kịch bản sản lượng / ngày (1 người)
B26: Kịch bản | C26: Video dài / ngày | D26: Short cắt / ngày | E26: Short native / ngày | F26: Phút cần | G26: Tỷ lệ dùng
B27: TỐI THIỂU — tuần 1–4 (mức tháng đầu) | C27: 0.5 | D27: =C27*ThongSo!$B$10 -> 2.5 | E27: 0 | F27: =C27*(D$15+D$18)+E27*D$19 -> 230 | G27: =F27/$D$22 -> 0.54761905
B28: TIÊU CHUẨN — từ tháng 2 | C28: 1 | D28: =C28*ThongSo!$B$10 -> 5 | E28: 1 | F28: =C28*(E$15+E$18)+E28*E$19 -> 289 | G28: =F28/$D$22 -> 0.68809524
B29: TỐI ĐA — 1 người thành thạo | C29: 1.5 | D29: =C29*ThongSo!$B$10 -> 7.5 | E29: 0 | F29: =C29*(E$15+E$18)+E29*E$19 -> 388.5 | G29: =F29/$D$22 -> 0.925
A31: Trần đăng khuyến nghị / 1 kênh
B32: Nền tảng | C32: Loại | D32: Tối thiểu | E32: Tối đa | F32: Ghi chú
B33: YouTube | C33: Video dài ≥ 15 phút | D33: 2/tuần | E33: 1/ngày | F33: Kênh A ~3/tuần, Kênh B ~2/tuần ở gói B
B34: YouTube | C34: Shorts | D34: 1/ngày | E34: 4/ngày | F34: Mọi short gắn Related video về bản dài
B35: TikTok | C35: Video dọc | D35: 1/ngày | E35: 3/ngày | F35: Kênh A; Kênh B hạn chế (quy định tài chính)
B36: Facebook / Instagram | C36: Reels | D36: 1/ngày | E36: 2/ngày | F36: Kênh B: kiểm tra quy định quảng cáo tài chính của Meta
A38: So sánh thời gian Kênh A: quy trình hiện tại vs HeyGen tất cả trong một (Video Agent + trình dựng)
B39: Hạng mục | C39: Hiện tại · tháng đầu | D39: Hiện tại · thành thạo | E39: HeyGen · tháng đầu | F39: HeyGen · thành thạo | G39: Ghi chú
B40: Bước 1–4: nghiên cứu, test & quay màn hình, kịch bản, Cổng 1 | C40: =SUM(D5:D8) -> 170 | D40: =SUM(E5:E8) -> 100 | E40: =C40 -> 170 | F40: =D40 -> 100 | G40: Giữ nguyên — Video Agent không test sản phẩm thay được
B41: Bước 5–8: giọng, người dẫn, B-roll, dựng | C41: =SUM(D9:D12) -> 200 | D41: =SUM(E9:E12) -> 107 | E41: 110 | F41: 60 | G41: HeyGen: Video Agent tạo bản nháp từ kịch bản → chèn quay màn hình, bảng giá, phụ đề trong trình dựng. ⚠️ Ước tính — đo ở video thử #2
B42: Bước 9–10: thumbnail/SEO, Cổng 2 | C42: =SUM(D13:D14) -> 50 | D42: =SUM(E13:E14) -> 27 | E42: =C42 -> 50 | F42: =D42 -> 27 | G42: Giữ nguyên
B43: Tổng phút / 1 video dài | C43: =SUM(C40:C42) -> 420 | D43: =SUM(D40:D42) -> 234 | E43: =SUM(E40:E42) -> 330 | F43: =SUM(F40:F42) -> 187
B44: Cắt 5 short | C44: =D18 -> 40 | D44: =E18 -> 25 | E44: =C44 -> 40 | F44: =D44 -> 25 | G44: Vẫn dùng tool cat_short.py
B45: Video dài / ngày / người (kèm cắt short) | C45: =$D$22/(C43+C44) -> 0.91304348 | D45: =$D$22/(D43+D44) -> 1.6216216 | E45: =$D$22/(E43+E44) -> 1.1351351 | F45: =$D$22/(F43+F44) -> 1.9811321
B47: Hiệu quả kinh tế (gói B, 12 video Kênh A / tháng) | E47: Tháng đầu | F47: Thành thạo
...

Sheet DoanhThu
A1: Doanh thu (affiliate + quảng cáo), hoà vốn & mục tiêu YPP
A2: Affiliate có từ video đầu tiên (không cần YPP). Quảng cáo YouTube chỉ có SAU khi vào YPP. Mọi tỷ lệ chuyển đổi là GIẢ ĐỊNH — thay bằng số thật từ dashboard affiliate sau 30 ngày.
A4: Thông số | B4: Giá trị | C4: Đơn vị | D4: Ghi chú / nguồn
A5: RPM quảng cáo Kênh A (Tech & Software) | B5: 10 | C5: USD | D5: Nguồn thứ cấp 2026: Tech & Software Reviews US$8–15; Technology US$10–20.
A6: RPM quảng cáo Kênh B (Finance/Crypto) | B6: 15 | C6: USD | D6: Finance US$10–30; Crypto US$8–20, biến động mạnh. Chỉ khi kênh được kiếm tiền.
A7: RPM Shorts | B7: 0.05 | C7: USD | D7: Phổ biến US$0,03–0,10.
A8: Lượt xem TB / video dài / tháng — Kênh A | B8: 2000 | C8: lượt | D8: Thận trọng cho 3 tháng đầu. Nhập số thật từ YouTube Studio.
A9: Lượt xem TB / video dài / tháng — Kênh B | B9: 2000 | C9: lượt | D9: Thận trọng cho 3 tháng đầu.
A10: Lượt xem TB / short / tháng | B10: 3000 | C10: lượt
A11: Gói đang dùng (A/B/C) | B11: B
A12: Chi phí nhân sự / tháng | B12: 15000000 | C12: VND | D12: GIẢ ĐỊNH — thay bằng số thực tế.
A13: Kênh A đã vào YPP? | B13: Chưa | D13: Gõ Có / Chưa
A14: Kênh B đã vào YPP? | B14: Chưa | D14: Gõ Có / Chưa
A16: Phễu affiliate (giả định thận trọng — sửa theo số thật)
A17: Mảng | B17: Kênh | C17: Tỷ trọng lượt xem trong kênh | D17: CTR link mô tả | E17: Tỷ lệ chuyển đổi / click | F17: Hoa hồng TB / chuyển đổi (USD) | G17: Doanh thu / 1.000 lượt xem kênh (USD) | H17: Ghi chú
A18: SaaS & AI tool | B18: A | C18: 0.75 | D18: 0.02 | E18: 0.02 | F18: 40 | G18: =C18*1000*D18*E18*F18 -> 12 | H18: 20–50% định kỳ; quy về 1 khoản TB (chưa tính tái tục).
A19: SPVL (Amazon) | B19: A | C19: 0.25 | D19: 0.03 | E19: 0.05 | F19: 2.4 | G19: =C19*1000*D19*E19*F19 -> 0.9 | H19: Đơn TB US$80 × ~3% (điện tử ~2%).
A20: Forex (CPA) | B20: B | C20: 0.5 | D20: 0.015 | E20: 0.01 | F20: 400 | G20: =C20*1000*D20*E20*F20 -> 30 | H20: CPA phổ biến US$200–1.200/khách đủ điều kiện.
A21: Crypto (chia phí) | B21: B | C21: 0.5 | D21: 0.015 | E21: 0.02 | F21: 75 | G21: =C21*1000*D21*E21*F21 -> 11.25 | H21: 20–50% phí giao dịch; quy về giá trị trọn đời TB.
A22: Affiliate / 1.000 lượt xem — Kênh A | G22: =SUMIFS(G18:G21,B18:B21,"A") -> 12.9
A23: Affiliate / 1.000 lượt xem — Kênh B | G23: =SUMIFS(G18:G21,B18:B21,"B") -> 41.25
A24: Kiểm tra tỷ trọng mỗi kênh = 100% | G24: =IF(AND(ABS(SUMIFS(C18:C21,B18:B21,"A")-1)<0.0001,ABS(SUMIFS(C18:C21,B18:B21,"B")-1)<0.0001),"OK","SAI") -> OK
A26: Kết quả theo tháng
A27: Chi phí công cụ / tháng (USD) | B27: =INDEX(ChiPhiVideo!$B$56:$D$56,MATCH($B$11,ChiPhiVideo!$B$38:$D$38,0)) -> 761.189
A28: Chi phí nhân sự / tháng (USD) | B28: =B12/ThongSo!$B$5 -> 566.03774
A29: Tổng chi phí / tháng (USD) | B29: =B27+B28 -> 1327.2267
A30: Video dài Kênh A / tháng | B30: =INDEX(ChiPhiVideo!$B$42:$D$42,MATCH($B$11,ChiPhiVideo!$B$38:$D$38,0)) -> 12
A31: Video dài Kênh B / tháng | B31: =INDEX(ChiPhiVideo!$B$43:$D$43,MATCH($B$11,ChiPhiVideo!$B$38:$D$38,0)) -> 8
A32: Short / tháng | B32: =INDEX(ChiPhiVideo!$B$44:$D$44,MATCH($B$11,ChiPhiVideo!$B$38:$D$38,0))+INDEX(ChiPhiVideo!$B$45:$D$45,MATCH($B$11,ChiPhiVideo!$B$38:$D$38,0)) -> 120
A33: Doanh thu / 1.000 lượt xem — Kênh A (affiliate + QC nếu có YPP) | B33: =G22+IF(B13="Có",B5,0) -> 12.9
A34: Doanh thu / 1.000 lượt xem — Kênh B | B34: =G23+IF(B14="Có",B6,0) -> 41.25
A35: Doanh thu Kênh A (USD) | B35: =B30*B8*B33/1000 -> 309.6
A36: Doanh thu Kênh B (USD) | B36: =B31*B9*B34/1000 -> 660
A37: Doanh thu Shorts (USD, khi Kênh A có YPP) | B37: =IF(B13="Có",B32*B10*B7/1000,0) -> 0
A38: Tổng doanh thu (USD) | B38: =B35+B36+B37 -> 969.6
A39: Lãi / lỗ (USD) | B39: =B38-B29 -> -357.62674
A40: Lãi / lỗ (VND) | B40: =B39*ThongSo!$B$5 -> -9477108.5
A41: Lượt xem / video dài để hoà vốn CÔNG CỤ | B41: =IF((B30*B33+B31*B34)>0,MAX(0,B27-B37)/((B30*B33+B31*B34)/1000),0) -> 1570.1093
A42: Lượt xem / video dài để hoà vốn TOÀN BỘ (gồm nhân sự) | B42: =IF((B30*B33+B31*B34)>0,MAX(0,B29-B37)/((B30*B33+B31*B34)/1000),0) -> 2737.6789
A44: Mục tiêu YPP Kênh A theo ngưỡng cũ (trước 31/01/2027)
...

Sheet LichDang
A1: Khung giờ đăng — giờ Việt Nam ↔ giờ New York (ET)
A2: Mỹ đổi giờ mùa đông 01/11/2026 → chênh 12 giờ (đến 14/03/2027). Mọi bài đều HẸN GIỜ.
A4: Chênh lệch giờ VN − ET (giờ) | B4: 12
A5: Chênh lệch giờ VN − CET/Paris (giờ) | B5: 6
A7: Kênh / nền tảng | B7: Loại | C7: Giờ đăng (giờ VN) | D7: Giờ New York (ET) | E7: Giờ Paris (CET) | F7: Tần suất | G7: Lý do
A8: A · YouTube | B8: Video dài | C8: 0.083333333 | D8: =MOD(C8-$B$4/24,1) -> 0.58333333 | E8: =MOD(C8-$B$5/24,1) -> 0.83333333 | F8: T3, T5, T7 | G8: 14:00 ET — người dùng B2B/tech xem giờ nghỉ trưa–chiều
A9: B · YouTube | B9: Video dài | C9: 0.125 | D9: =MOD(C9-$B$4/24,1) -> 0.625 | E9: =MOD(C9-$B$5/24,1) -> 0.875 | F9: T2, T4 | G9: 15:00 ET
A10: A · YouTube | B10: Short #1 | C10: 0.875 | D10: =MOD(C10-$B$4/24,1) -> 0.375 | E10: =MOD(C10-$B$5/24,1) -> 0.625 | F10: Hằng ngày | G10: Sáng Mỹ / chiều châu Âu
A11: A · YouTube | B11: Short #2 | C11: 0.041666667 | D11: =MOD(C11-$B$4/24,1) -> 0.54166667 | E11: =MOD(C11-$B$5/24,1) -> 0.79166667 | F11: Hằng ngày | G11: Trưa Mỹ / tối châu Âu
A12: B · YouTube | B12: Short #1 | C12: 0.95833333 | D12: =MOD(C12-$B$4/24,1) -> 0.45833333 | E12: =MOD(C12-$B$5/24,1) -> 0.70833333 | F12: Hằng ngày | G12: 11:00 ET — giờ thị trường Mỹ mở
A13: B · YouTube | B13: Short #2 | C13: 0.29166667 | D13: =MOD(C13-$B$4/24,1) -> 0.79166667 | E13: =MOD(C13-$B$5/24,1) -> 0.041666667 | F13: Hằng ngày | G13: Tối Mỹ
A14: A · TikTok | B14: Short | C14: 0.25 | D14: =MOD(C14-$B$4/24,1) -> 0.75 | E14: =MOD(C14-$B$5/24,1) -> 0 | F14: 1–2/ngày | G14: 18:00 ET
A15: A · Facebook/Instagram | B15: Reels | C15: 0 | D15: =MOD(C15-$B$4/24,1) -> 0.5 | E15: =MOD(C15-$B$5/24,1) -> 0.75 | F15: 1/ngày | G15: 12:00 ET / 18:00 Paris

Sheet TheoDoi
A1: Theo dõi sản xuất từng video
A2: Mỗi dòng = 1 video dài. Chọn từ danh sách. Dòng 5 là VÍ DỤ — xoá khi dùng thật.
A4: Mã video | B4: Kênh | C4: Mảng | D4: Sản phẩm / chủ đề (EN) | E4: Chương trình affiliate | F4: Ngày giao | G4: Quay màn hình thật | H4: Kịch bản | I4: CỔNG 1 | J4: Giọng | K4: Người dẫn AI | L4: B-roll | M4: Dựng | N4: CỔNG 2 | O4: Disclosure đủ (lời + chữ + mô tả) | P4: Ngày đăng | Q4: Link YouTube | R4: Số short | S4: Lỗi ở Cổng 2 | T4: Nguyên nhân gốc → đã sửa?
A5: V001 | B5: A | C5: AI tool | D5: Notion AI Review 2026: Worth It? | E5: Có — 20% định kỳ | F5: 46310 | G5: Xong | H5: Xong | I5: Đạt | J5: Xong | K5: Đang làm | L5: Chưa làm | M5: Chưa làm | N5: Chưa duyệt | O5: Chưa | R5: 0

Sheet KPI
A1: KPI hằng tuần (mỗi kênh 1 bảng hoặc thêm cột Kênh)
A2: Nhập số từ YouTube Studio & dashboard affiliate mỗi thứ Hai. Dòng 'Mục tiêu' chỉnh được. Dòng tuần 1 là VÍ DỤ.
A4: Tuần | B4: Video dài đã đăng | C4: Short đã đăng | D4: CTR thumbnail | E4: AVD (% thời lượng) | F4: Lượt xem video dài | G4: Lượt xem Shorts | H4: Người đăng ký mới | I4: Giờ xem tích luỹ | J4: Click affiliate | K4: Chuyển đổi affiliate | L4: Doanh thu affiliate (USD) | M4: % video phải sửa sau Cổng 2 | N4: Chi phí tuần (USD) | O4: Chi phí / 1.000 lượt xem (USD)
A5: Mục tiêu | B5: 5 | C5: 28 | D5: 0.05 | E5: 0.3 | F5: 5000 | G5: 50000 | H5: 120 | I5: 4000 | J5: 100 | K5: 3 | L5: 150 | M5: 0.1 | N5: 175 | O5: 3
A6: Tuần 1 | B6: 3 | C6: 15 | D6: 0.041 | E6: 0.27 | F6: 1500 | G6: 9000 | H6: 40 | I6: =IF(F6="","",SUMPRODUCT($F$6:F6,$E$6:E6)*ThongSo!$B$6/3600) -> 121.5 | J6: 22 | K6: 0 | L6: 0 | M6: 0.33 | N6: 170 | O6: =IF(OR(N6="",F6+G6=0),"",N6/(F6+G6)*1000) -> 16.190476
A7: Tuần 2 | I7: =IF(F7="","",SUMPRODUCT($F$6:F7,$E$6:E7)*ThongSo!$B$6/3600) | O7: =IF(OR(N7="",F7+G7=0),"",N7/(F7+G7)*1000)
A8: Tuần 3 | I8: =IF(F8="","",SUMPRODUCT($F$6:F8,$E$6:E8)*ThongSo!$B$6/3600) | O8: =IF(OR(N8="",F8+G8=0),"",N8/(F8+G8)*1000)
A9: Tuần 4 | I9: =IF(F9="","",SUMPRODUCT($F$6:F9,$E$6:E9)*ThongSo!$B$6/3600) | O9: =IF(OR(N9="",F9+G9=0),"",N9/(F9+G9)*1000)
A10: Tuần 5 | I10: =IF(F10="","",SUMPRODUCT($F$6:F10,$E$6:E10)*ThongSo!$B$6/3600) | O10: =IF(OR(N10="",F10+G10=0),"",N10/(F10+G10)*1000)
A11: Tuần 6 | I11: =IF(F11="","",SUMPRODUCT($F$6:F11,$E$6:E11)*ThongSo!$B$6/3600) | O11: =IF(OR(N11="",F11+G11=0),"",N11/(F11+G11)*1000)
A12: Tuần 7 | I12: =IF(F12="","",SUMPRODUCT($F$6:F12,$E$6:E12)*ThongSo!$B$6/3600) | O12: =IF(OR(N12="",F12+G12=0),"",N12/(F12+G12)*1000)
A13: Tuần 8 | I13: =IF(F13="","",SUMPRODUCT($F$6:F13,$E$6:E13)*ThongSo!$B$6/3600) | O13: =IF(OR(N13="",F13+G13=0),"",N13/(F13+G13)*1000)
A14: Tuần 9 | I14: =IF(F14="","",SUMPRODUCT($F$6:F14,$E$6:E14)*ThongSo!$B$6/3600) | O14: =IF(OR(N14="",F14+G14=0),"",N14/(F14+G14)*1000)
A15: Tuần 10 | I15: =IF(F15="","",SUMPRODUCT($F$6:F15,$E$6:E15)*ThongSo!$B$6/3600) | O15: =IF(OR(N15="",F15+G15=0),"",N15/(F15+G15)*1000)
A16: Tuần 11 | I16: =IF(F16="","",SUMPRODUCT($F$6:F16,$E$6:E16)*ThongSo!$B$6/3600) | O16: =IF(OR(N16="",F16+G16=0),"",N16/(F16+G16)*1000)
A17: Tuần 12 | I17: =IF(F17="","",SUMPRODUCT($F$6:F17,$E$6:E17)*ThongSo!$B$6/3600) | O17: =IF(OR(N17="",F17+G17=0),"",N17/(F17+G17)*1000)
A18: Tuần 13 | I18: =IF(F18="","",SUMPRODUCT($F$6:F18,$E$6:E18)*ThongSo!$B$6/3600) | O18: =IF(OR(N18="",F18+G18=0),"",N18/(F18+G18)*1000)
... A29: Tuần 24 | I29: =IF(F29="","",SUMPRODUCT($F$6:F29,$E$6:E29)*ThongSo!$B$6/3600) | O29: =IF(OR(N29="",F29+G29=0),"",N29/(F29+G29)*1000)
